Workbook
Name FAPool: 'FA Pool'!$P$2:$P$741

Sheet My Roster
A1: Player | B1: NHL | C1: Pos | D1: Eligible | E1: Slot | F1: Status | G1: Age | H1: Salary | I1: FPts 25/26 | J1: FPts 25/26 per $M | K1: FP/G 25/26 | L1: FP/G 25/26 per $M | M1: Fantrax 26/27 | N1: A&G 26/27 | O1: Consensus 26/27 | P1: Change | Q1: Cons. per $M | R1: ADP | S1: · row | T1: SCENARIO 1 | W1: <name this plan> | AD1: SCENARIO 2 | AG1: <name this plan> | AN1: SCENARIO 3 | AQ1: <name this plan> | AX1: · drop order
T2: Player | U2: Pos | V2: Age | W2: Salary | X2: FPts 25/26 | Y2: Cons 26/27 | Z2: Cons/$M | AA2: ADP | AB2: Own | AD2: Player | AE2: Pos | AF2: Age | AG2: Salary | AH2: FPts 25/26 | AI2: Cons 26/27 | AJ2: Cons/$M | AK2: ADP | AL2: Own | AN2: Player | AO2: Pos | AP2: Age | AQ2: Salary | AR2: FPts 25/26 | AS2: Cons 26/27 | AT2: Cons/$M | AU2: ADP | AV2: Own
A3: ROSTER - counts toward the cap and scores | T3: ROSTER - counts toward the cap and scores | AD3: ROSTER - counts toward the cap and scores | AN3: ROSTER - counts toward the cap and scores
A4: =IFERROR(IF(INDEX(Rosters!$B$2:$B$516,$S4)="","",INDEX(Rosters!$B$2:$B$516,$S4)),"") | B4: =IFERROR(IF(INDEX(Rosters!$C$2:$C$516,$S4)="","",INDEX(Rosters!$C$2:$C$516,$S4)),"") | C4: =IFERROR(IF(INDEX(Rosters!$D$2:$D$516,$S4)="","",INDEX(Rosters!$D$2:$D$516,$S4)),"") | D4: =IFERROR(IF(INDEX(Rosters!$E$2:$E$516,$S4)="","",INDEX(Rosters!$E$2:$E$516,$S4)),"") | E4: =IFERROR(IF(INDEX(Rosters!$F$2:$F$516,$S4)="","",INDEX(Rosters!$F$2:$F$516,$S4)),"") | F4: =IFERROR(IF(INDEX(Rosters!$G$2:$G$516,$S4)="","",INDEX(Rosters!$G$2:$G$516,$S4)),"") | G4: =IFERROR(IF(INDEX(Rosters!$H$2:$H$516,$S4)="","",INDEX(Rosters!$H$2:$H$516,$S4)),"") | H4: =IFERROR(IF(INDEX(Rosters!$I$2:$I$516,$S4)="","",INDEX(Rosters!$I$2:$I$516,$S4)),"") | I4: =IFERROR(IF(INDEX(Rosters!$J$2:$J$516,$S4)="","",INDEX(Rosters!$J$2:$J$516,$S4)),"") | J4: =IFERROR(IF(INDEX(Rosters!$S$2:$S$516,$S4)="","",INDEX(Rosters!$S$2:$S$516,$S4)),"") | K4: =IFERROR(IF(INDEX(Rosters!$K$2:$K$516,$S4)="","",INDEX(Rosters!$K$2:$K$516,$S4)),"") | L4: =IFERROR(IF(INDEX(Rosters!$T$2:$T$516,$S4)="","",INDEX(Rosters!$T$2:$T$516,$S4)),"") | M4: =IFERROR(IF(INDEX(Rosters!$L$2:$L$516,$S4)="","",INDEX(Rosters!$L$2:$L$516,$S4)),"") | N4: =IFERROR(IF(INDEX(Rosters!$Q$2:$Q$516,$S4)="","",INDEX(Rosters!$Q$2:$Q$516,$S4)),"") | O4: =IFERROR(IF(INDEX(Rosters!$R$2:$R$516,$S4)="","",INDEX(Rosters!$R$2:$R$516,$S4)),"") | P4: =IFERROR(IF(INDEX(Rosters!$N$2:$N$516,$S4)="","",INDEX(Rosters!$N$2:$N$516,$S4)),"") | Q4: =IFERROR(IF(INDEX(Rosters!$O$2:$O$516,$S4)="","",INDEX(Rosters!$O$2:$O$516,$S4)),"") | R4: =IFERROR(IF(INDEX(Rosters!$P$2:$P$516,$S4)="","",INDEX(Rosters!$P$2:$P$516,$S4)),"") | S4: =IFERROR(MATCH('League Settings'!$B$2&"|ACTIVE|"&1,Rosters!$AD$2:$AD$516,0),"") | T4: Zach Werenski (CBJ D) | U4: =IFERROR(IF(INDEX('Player Pool'!$D$2:$D$8725,MATCH($T4,'Player Pool'!$Z$2:$Z$8725,0))="","",INDEX('Player Pool'!$D$2:$D$8725,MATCH($T4,'Player Pool'!$Z$2:$Z$8725,0))),"") | V4: =IFERROR(IF(INDEX('Player Pool'!$E$2:$E$8725,MATCH($T4,'Player Pool'!$Z$2:$Z$8725,0))="","",INDEX('Player Pool'!$E$2:$E$8725,MATCH($T4,'Player Pool'!$Z$2:$Z$8725,0))),"") | W4: =IFERROR(IF($T4="","",IF(ISNUMBER(IFERROR(INDEX(Rosters!$I$2:$I$516,MATCH(INDEX('Player Pool'!$V$2:$V$8725,MATCH($T4,'Player Pool'!$Z$2:$Z$8725,0)),Rosters!$W$2:$W$516,0)),"")),IFERROR(INDEX(Rosters!$I$2:$I$516,MATCH(INDEX('Player Pool'!$V$2:$V$8725,MATCH($T4,'Player Pool'!$Z$2:$Z$8725,0)),Rosters!$W$2:$W$516,0)),""),INDEX('Player Pool'!$H$2:$H$8725,MATCH($T4,'Player Pool'!$Z$2:$Z$8725,0)))),"") | X4: =IFERROR(IF(INDEX('Player Pool'!$I$2:$I$8725,MATCH($T4,'Player Pool'!$Z$2:$Z$8725,0))="","",INDEX('Player Pool'!$I$2:$I$8725,MATCH($T4,'Player Pool'!$Z$2:$Z$8725,0))),"") | Y4: =IFERROR(IF(INDEX('Player Pool'!$P$2:$P$8725,MATCH($T4,'Player Pool'!$Z$2:$Z$8725,0))="","",INDEX('Player Pool'!$P$2:$P$8725,MATCH($T4,'Player Pool'!$Z$2:$Z$8725,0))),"") | Z4: =IFERROR(IF(INDEX('Player Pool'!$R$2:$R$8725,MATCH($T4,'Player Pool'!$Z$2:$Z$8725,0))="","",INDEX('Player Pool'!$R$2:$R$8725,MATCH($T4,'Player Pool'!$Z$2:$Z$8725,0))),"") | AA4: =IFERROR(IF(INDEX('Player Pool'!$U$2:$U$8725,MATCH($T4,'Player Pool'!$Z$2:$Z$8725,0))="","",INDEX('Player Pool'!$U$2:$U$8725,MATCH($T4,'Player Pool'!$Z$2:$Z$8725,0))),"") | AB4: =IFERROR(IF($T4="","",IF(INDEX('Player Pool'!$G$2:$G$8725,MATCH($T4,'Player Pool'!$Z$2:$Z$8725,0))="FA","FA",IF(INDEX('Player Pool'!$G$2:$G$8725,MATCH($T4,'Player Pool'!$Z$2:$Z$8725,0))='League Settings'!$B$2,"MINE","TAKEN"))),"") | AD4: Zach Werenski (CBJ D) | AE4: =IFERROR(IF(INDEX('Player Pool'!$D$2:$D$8725,MATCH($AD4,'Player Pool'!$Z$2:$Z$8725,0))="","",INDEX('Player Pool'!$D$2:$D$8725,MATCH($AD4,'Player Pool'!$Z$2:$Z$8725,0))),"") | AF4: =IFERROR(IF(INDEX('Player Pool'!$E$2:$E$8725,MATCH($AD4,'Player Pool'!$Z$2:$Z$8725,0))="","",INDEX('Player Pool'!$E$2:$E$8725,MATCH($AD4,'Player Pool'!$Z$2:$Z$8725,0))),"") | AG4: =IFERROR(IF($AD4="","",IF(ISNUMBER(IFERROR(INDEX(Rosters!$I$2:$I$516,MATCH(INDEX('Player Pool'!$V$2:$V$8725,MATCH($AD4,'Player Pool'!$Z$2:$Z$8725,0)),Rosters!$W$2:$W$516,0)),"")),IFERROR(INDEX(Rosters!$I$2:$I$516,MATCH(INDEX('Player Pool'!$V$2:$V$8725,MATCH($AD4,'Player Pool'!$Z$2:$Z$8725,0)),Rosters!$W$2:$W$516,0)),""),INDEX('Player Pool'!$H$2:$H$8725,MATCH($AD4,'Player Pool'!$Z$2:$Z$8725,0)))),"") | AH4: =IFERROR(IF(INDEX('Player Pool'!$I$2:$I$8725,MATCH($AD4,'Player Pool'!$Z$2:$Z$8725,0))="","",INDEX('Player Pool'!$I$2:$I$8725,MATCH($AD4,'Player Pool'!$Z$2:$Z$8725,0))),"") | AI4: =IFERROR(IF(INDEX('Player Pool'!$P$2:$P$8725,MATCH($AD4,'Player Pool'!$Z$2:$Z$8725,0))="","",INDEX('Player Pool'!$P$2:$P$8725,MATCH($AD4,'Player Pool'!$Z$2:$Z$8725,0))),"") | AJ4: =IFERROR(IF(INDEX('Player Pool'!$R$2:$R$8725,MATCH($AD4,'Player Pool'!$Z$2:$Z$8725,0))="","",INDEX('Player Pool'!$R$2:$R$8725,MATCH($AD4,'Player Pool'!$Z$2:$Z$8725,0))),"") | AK4: =IFERROR(IF(INDEX('Player Pool'!$U$2:$U$8725,MATCH($AD4,'Player Pool'!$Z$2:$Z$8725,0))="","",INDEX('Player Pool'!$U$2:$U$8725,MATCH($AD4,'Player Pool'!$Z$2:$Z$8725,0))),"") | AL4: =IFERROR(IF($AD4="","",IF(INDEX('Player Pool'!$G$2:$G$8725,MATCH($AD4,'Player Pool'!$Z$2:$Z$8725,0))="FA","FA",IF(INDEX('Player Pool'!$G$2:$G$8725,MATCH($AD4,'Player Pool'!$Z$2:$Z$8725,0))='League Settings'!$B$2,"MINE","TAKEN"))),"") | AN4: Zach Werenski (CBJ D) | AO4: =IFERROR(IF(INDEX('Player Pool'!$D$2:$D$8725,MATCH($AN4,'Player Pool'!$Z$2:$Z$8725,0))="","",INDEX('Player Pool'!$D$2:$D$8725,MATCH($AN4,'Player Pool'!$Z$2:$Z$8725,0))),"") | AP4: =IFERROR(IF(INDEX('Player Pool'!$E$2:$E$8725,MATCH($AN4,'Player Pool'!$Z$2:$Z$8725,0))="","",INDEX('Player Pool'!$E$2:$E$8725,MATCH($AN4,'Player Pool'!$Z$2:$Z$8725,0))),"") | AQ4: =IFERROR(IF($AN4="","",IF(ISNUMBER(IFERROR(INDEX(Rosters!$I$2:$I$516,MATCH(INDEX('Player Pool'!$V$2:$V$8725,MATCH($AN4,'Player Pool'!$Z$2:$Z$8725,0)),Rosters!$W$2:$W$516,0)),"")),IFERROR(INDEX(Rosters!$I$2:$I$516,MATCH(INDEX('Player Pool'!$V$2:$V$8725,MATCH($AN4,'Player Pool'!$Z$2:$Z$8725,0)),Rosters!$W$2:$W$516,0)),""),INDEX('Player Pool'!$H$2:$H$8725,MATCH($AN4,'Player Pool'!$Z$2:$Z$8725,0)))),"") | AR4: =IFERROR(IF(INDEX('Player Pool'!$I$2:$I$8725,MATCH($AN4,'Player Pool'!$Z$2:$Z$8725,0))="","",INDEX('Player Pool'!$I$2:$I$8725,MATCH($AN4,'Player Pool'!$Z$2:$Z$8725,0))),"") | AS4: =IFERROR(IF(INDEX('Player Pool'!$P$2:$P$8725,MATCH($AN4,'Player Pool'!$Z$2:$Z$8725,0))="","",INDEX('Player Pool'!$P$2:$P$8725,MATCH($AN4,'Player Pool'!$Z$2:$Z$8725,0))),"") | AT4: =IFERROR(IF(INDEX('Player Pool'!$R$2:$R$8725,MATCH($AN4,'Player Pool'!$Z$2:$Z$8725,0))="","",INDEX('Player Pool'!$R$2:$R$8725,MATCH($AN4,'Player Pool'!$Z$2:$Z$8725,0))),"") | AU4: =IFERROR(IF(INDEX('Player Pool'!$U$2:$U$8725,MATCH($AN4,'Player Pool'!$Z$2:$Z$8725,0))="","",INDEX('Player Pool'!$U$2:$U$8725,MATCH($AN4,'Player Pool'!$Z$2:$Z$8725,0))),"") | AV4: =IFERROR(IF($AN4="","",IF(INDEX('Player Pool'!$G$2:$G$8725,MATCH($AN4,'Player Pool'!$Z$2:$Z$8725,0))="FA","FA",IF(INDEX('Player Pool'!$G$2:$G$8725,MATCH($AN4,'Player Pool'!$Z$2:$Z$8725,0))='League Settings'!$B$2,"MINE","TAKEN"))),"")
A5: =IFERROR(IF(INDEX(Rosters!$B$2:$B$516,$S5)="","",INDEX(Rosters!$B$2:$B$516,$S5)),"") | B5: =IFERROR(IF(INDEX(Rosters!$C$2:$C$516,$S5)="","",INDEX(Rosters!$C$2:$C$516,$S5)),"") | C5: =IFERROR(IF(INDEX(Rosters!$D$2:$D$516,$S5)="","",INDEX(Rosters!$D$2:$D$516,$S5)),"") | D5: =IFERROR(IF(INDEX(Rosters!$E$2:$E$516,$S5)="","",INDEX(Rosters!$E$2:$E$516,$S5)),"") | E5: =IFERROR(IF(INDEX(Rosters!$F$2:$F$516,$S5)="","",INDEX(Rosters!$F$2:$F$516,$S5)),"") | F5: =IFERROR(IF(INDEX(Rosters!$G$2:$G$516,$S5)="","",INDEX(Rosters!$G$2:$G$516,$S5)),"") | G5: =IFERROR(IF(INDEX(Rosters!$H$2:$H$516,$S5)="","",INDEX(Rosters!$H$2:$H$516,$S5)),"") | H5: =IFERROR(IF(INDEX(Rosters!$I$2:$I$516,$S5)="","",INDEX(Rosters!$I$2:$I$516,$S5)),"") | I5: =IFERROR(IF(INDEX(Rosters!$J$2:$J$516,$S5)="","",INDEX(Rosters!$J$2:$J$516,$S5)),"") | J5: =IFERROR(IF(INDEX(Rosters!$S$2:$S$516,$S5)="","",INDEX(Rosters!$S$2:$S$516,$S5)),"") | K5: =IFERROR(IF(INDEX(Rosters!$K$2:$K$516,$S5)="","",INDEX(Rosters!$K$2:$K$516,$S5)),"") | L5: =IFERROR(IF(INDEX(Rosters!$T$2:$T$516,$S5)="","",INDEX(Rosters!$T$2:$T$516,$S5)),"") | M5: =IFERROR(IF(INDEX(Rosters!$L$2:$L$516,$S5)="","",INDEX(Rosters!$L$2:$L$516,$S5)),"") | N5: =IFERROR(IF(INDEX(Rosters!$Q$2:$Q$516,$S5)="","",INDEX(Rosters!$Q$2:$Q$516,$S5)),"") | O5: =IFERROR(IF(INDEX(Rosters!$R$2:$R$516,$S5)="","",INDEX(Rosters!$R$2:$R$516,$S5)),"") | P5: =IFERROR(IF(INDEX(Rosters!$N$2:$N$516,$S5)="","",INDEX(Rosters!$N$2:$N$516,$S5)),"") | Q5: =IFERROR(IF(INDEX(Rosters!$O$2:$O$516,$S5)="","",INDEX(Rosters!$O$2:$O$516,$S5)),"") | R5: =IFERROR(IF(INDEX(Rosters!$P$2:$P$516,$S5)="","",INDEX(Rosters!$P$2:$P$516,$S5)),"") | S5: =IFERROR(MATCH('League Settings'!$B$2&"|ACTIVE|"&2,Rosters!$AD$2:$AD$516,0),"") | T5: Matthew Tkachuk (FLA RW) | U5: =IFERROR(IF(INDEX('Player Pool'!$D$2:$D$8725,MATCH($T5,'Player Pool'!$Z$2:$Z$8725,0))="","",INDEX('Player Pool'!$D$2:$D$8725,MATCH($T5,'Player Pool'!$Z$2:$Z$8725,0))),"") | V5: =IFERROR(IF(INDEX('Player Pool'!$E$2:$E$8725,MATCH($T5,'Player Pool'!$Z$2:$Z$8725,0))="","",INDEX('Player Pool'!$E$2:$E$8725,MATCH($T5,'Player Pool'!$Z$2:$Z$8725,0))),"") | W5: =IFERROR(IF($T5="","",IF(ISNUMBER(IFERROR(INDEX(Rosters!$I$2:$I$516,MATCH(INDEX('Player Pool'!$V$2:$V$8725,MATCH($T5,'Player Pool'!$Z$2:$Z$8725,0)),Rosters!$W$2:$W$516,0)),"")),IFERROR(INDEX(Rosters!$I$2:$I$516,MATCH(INDEX('Player Pool'!$V$2:$V$8725,MATCH($T5,'Player Pool'!$Z$2:$Z$8725,0)),Rosters!$W$2:$W$516,0)),""),INDEX('Player Pool'!$H$2:$H$8725,MATCH($T5,'Player Pool'!$Z$2:$Z$8725,0)))),"") | X5: =IFERROR(IF(INDEX('Player Pool'!$I$2:$I$8725,MATCH($T5,'Player Pool'!$Z$2:$Z$8725,0))="","",INDEX('Player Pool'!$I$2:$I$8725,MATCH($T5,'Player Pool'!$Z$2:$Z$8725,0))),"") | Y5: =IFERROR(IF(INDEX('Player Pool'!$P$2:$P$8725,MATCH($T5,'Player Pool'!$Z$2:$Z$8725,0))="","",INDEX('Player Pool'!$P$2:$P$8725,MATCH($T5,'Player Pool'!$Z$2:$Z$8725,0))),"") | Z5: =IFERROR(IF(INDEX('Player Pool'!$R$2:$R$8725,MATCH($T5,'Player Pool'!$Z$2:$Z$8725,0))="","",INDEX('Player Pool'!$R$2:$R$8725,MATCH($T5,'Player Pool'!$Z$2:$Z$8725,0))),"") | AA5: =IFERROR(IF(INDEX('Player Pool'!$U$2:$U$8725,MATCH($T5,'Player Pool'!$Z$2:$Z$8725,0))="","",INDEX('Player Pool'!$U$2:$U$8725,MATCH($T5,'Player Pool'!$Z$2:$Z$8725,0))),"") | AB5: =IFERROR(IF($T5="","",IF(INDEX('Player Pool'!$G$2:$G$8725,MATCH($T5,'Player Pool'!$Z$2:$Z$8725,0))="FA","FA",IF(INDEX('Player Pool'!$G$2:$G$8725,MATCH($T5,'Player Pool'!$Z$2:$Z$8725,0))='League Settings'!$B$2,"MINE","TAKEN"))),"") | AD5: Matthew Tkachuk (FLA RW) | AE5: =IFERROR(IF(INDEX('Player Pool'!$D$2:$D$8725,MATCH($AD5,'Player Pool'!$Z$2:$Z$8725,0))="","",INDEX('Player Pool'!$D$2:$D$8725,MATCH($AD5,'Player Pool'!$Z$2:$Z$8725,0))),"") | AF5: =IFERROR(IF(INDEX('Player Pool'!$E$2:$E$8725,MATCH($AD5,'Player Pool'!$Z$2:$Z$8725,0))="","",INDEX('Player Pool'!$E$2:$E$8725,MATCH($AD5,'Player Pool'!$Z$2:$Z$8725,0))),"") | AG5: =IFERROR(IF($AD5="","",IF(ISNUMBER(IFERROR(INDEX(Rosters!$I$2:$I$516,MATCH(INDEX('Player Pool'!$V$2:$V$8725,MATCH($AD5,'Player Pool'!$Z$2:$Z$8725,0)),Rosters!$W$2:$W$516,0)),"")),IFERROR(INDEX(Rosters!$I$2:$I$516,MATCH(INDEX('Player Pool'!$V$2:$V$8725,MATCH($AD5,'Player Pool'!$Z$2:$Z$8725,0)),Rosters!$W$2:$W$516,0)),""),INDEX('Player Pool'!$H$2:$H$8725,MATCH($AD5,'Player Pool'!$Z$2:$Z$8725,0)))),"") | AH5: =IFERROR(IF(INDEX('Player Pool'!$I$2:$I$8725,MATCH($AD5,'Player Pool'!$Z$2:$Z$8725,0))="","",INDEX('Player Pool'!$I$2:$I$8725,MATCH($AD5,'Player Pool'!$Z$2:$Z$8725,0))),"") | AI5: =IFERROR(IF(INDEX('Player Pool'!$P$2:$P$8725,MATCH($AD5,'Player Pool'!$Z$2:$Z$8725,0))="","",INDEX('Player Pool'!$P$2:$P$8725,MATCH($AD5,'Player Pool'!$Z$2:$Z$8725,0))),"") | AJ5: =IFERROR(IF(INDEX('Player Pool'!$R$2:$R$8725,MATCH($AD5,'Player Pool'!$Z$2:$Z$8725,0))="","",INDEX('Player Pool'!$R$2:$R$8725,MATCH($AD5,'Player Pool'!$Z$2:$Z$8725,0))),"") | AK5: =IFERROR(IF(INDEX('Player Pool'!$U$2:$U$8725,MATCH($AD5,'Player Pool'!$Z$2:$Z$8725,0))="","",INDEX('Player Pool'!$U$2:$U$8725,MATCH($AD5,'Player Pool'!$Z$2:$Z$8725,0))),"") | AL5: =IFERROR(IF($AD5="","",IF(INDEX('Player Pool'!$G$2:$G$8725,MATCH($AD5,'Player Pool'!$Z$2:$Z$8725,0))="FA","FA",IF(INDEX('Player Pool'!$G$2:$G$8725,MATCH($AD5,'Player Pool'!$Z$2:$Z$8725,0))='League Settings'!$B$2,"MINE","TAKEN"))),"") | AN5: Matthew Tkachuk (FLA RW) | AO5: =IFERROR(IF(INDEX('Player Pool'!$D$2:$D$8725,MATCH($AN5,'Player Pool'!$Z$2:$Z$8725,0))="","",INDEX('Player Pool'!$D$2:$D$8725,MATCH($AN5,'Player Pool'!$Z$2:$Z$8725,0))),"") | AP5: =IFERROR(IF(INDEX('Player Pool'!$E$2:$E$8725,MATCH($AN5,'Player Pool'!$Z$2:$Z$8725,0))="","",INDEX('Player Pool'!$E$2:$E$8725,MATCH($AN5,'Player Pool'!$Z$2:$Z$8725,0))),"") | AQ5: =IFERROR(IF($AN5="","",IF(ISNUMBER(IFERROR(INDEX(Rosters!$I$2:$I$516,MATCH(INDEX('Player Pool'!$V$2:$V$8725,MATCH($AN5,'Player Pool'!$Z$2:$Z$8725,0)),Rosters!$W$2:$W$516,0)),"")),IFERROR(INDEX(Rosters!$I$2:$I$516,MATCH(INDEX('Player Pool'!$V$2:$V$8725,MATCH($AN5,'Player Pool'!$Z$2:$Z$8725,0)),Rosters!$W$2:$W$516,0)),""),INDEX('Player Pool'!$H$2:$H$8725,MATCH($AN5,'Player Pool'!$Z$2:$Z$8725,0)))),"") | AR5: =IFERROR(IF(INDEX('Player Pool'!$I$2:$I$8725,MATCH($AN5,'Player Pool'!$Z$2:$Z$8725,0))="","",INDEX('Player Pool'!$I$2:$I$8725,MATCH($AN5,'Player Pool'!$Z$2:$Z$8725,0))),"") | AS5: =IFERROR(IF(INDEX('Player Pool'!$P$2:$P$8725,MATCH($AN5,'Player Pool'!$Z$2:$Z$8725,0))="","",INDEX('Player Pool'!$P$2:$P$8725,MATCH($AN5,'Player Pool'!$Z$2:$Z$8725,0))),"") | AT5: =IFERROR(IF(INDEX('Player Pool'!$R$2:$R$8725,MATCH($AN5,'Player Pool'!$Z$2:$Z$8725,0))="","",INDEX('Player Pool'!$R$2:$R$8725,MATCH($AN5,'Player Pool'!$Z$2:$Z$8725,0))),"") | AU5: =IFERROR(IF(INDEX('Player Pool'!$U$2:$U$8725,MATCH($AN5,'Player Pool'!$Z$2:$Z$8725,0))="","",INDEX('Player Pool'!$U$2:$U$8725,MATCH($AN5,'Player Pool'!$Z$2:$Z$8725,0))),"") | AV5: =IFERROR(IF($AN5="","",IF(INDEX('Player Pool'!$G$2:$G$8725,MATCH($AN5,'Player Pool'!$Z$2:$Z$8725,0))="FA","FA",IF(INDEX('Player Pool'!$G$2:$G$8725,MATCH($AN5,'Player Pool'!$Z$2:$Z$8725,0))='League Settings'!$B$2,"MINE","TAKEN"))),"")
A6: =IFERROR(IF(INDEX(Rosters!$B$2:$B$516,$S6)="","",INDEX(Rosters!$B$2:$B$516,$S6)),"") | B6: =IFERROR(IF(INDEX(Rosters!$C$2:$C$516,$S6)="","",INDEX(Rosters!$C$2:$C$516,$S6)),"") | C6: =IFERROR(IF(INDEX(Rosters!$D$2:$D$516,$S6)="","",INDEX(Rosters!$D$2:$D$516,$S6)),"") | D6: =IFERROR(IF(INDEX(Rosters!$E$2:$E$516,$S6)="","",INDEX(Rosters!$E$2:$E$516,$S6)),"") | E6: =IFERROR(IF(INDEX(Rosters!$F$2:$F$516,$S6)="","",INDEX(Rosters!$F$2:$F$516,$S6)),"") | F6: =IFERROR(IF(INDEX(Rosters!$G$2:$G$516,$S6)="","",INDEX(Rosters!$G$2:$G$516,$S6)),"") | G6: =IFERROR(IF(INDEX(Rosters!$H$2:$H$516,$S6)="","",INDEX(Rosters!$H$2:$H$516,$S6)),"") | H6: =IFERROR(IF(INDEX(Rosters!$I$2:$I$516,$S6)="","",INDEX(Rosters!$I$2:$I$516,$S6)),"") | I6: =IFERROR(IF(INDEX(Rosters!$J$2:$J$516,$S6)="","",INDEX(Rosters!$J$2:$J$516,$S6)),"") | J6: =IFERROR(IF(INDEX(Rosters!$S$2:$S$516,$S6)="","",INDEX(Rosters!$S$2:$S$516,$S6)),"") | K6: =IFERROR(IF(INDEX(Rosters!$K$2:$K$516,$S6)="","",INDEX(Rosters!$K$2:$K$516,$S6)),"") | L6: =IFERROR(IF(INDEX(Rosters!$T$2:$T$516,$S6)="","",INDEX(Rosters!$T$2:$T$516,$S6)),"") | M6: =IFERROR(IF(INDEX(Rosters!$L$2:$L$516,$S6)="","",INDEX(Rosters!$L$2:$L$516,$S6)),"") | N6: =IFERROR(IF(INDEX(Rosters!$Q$2:$Q$516,$S6)="","",INDEX(Rosters!$Q$2:$Q$516,$S6)),"") | O6: =IFERROR(IF(INDEX(Rosters!$R$2:$R$516,$S6)="","",INDEX(Rosters!$R$2:$R$516,$S6)),"") | P6: =IFERROR(IF(INDEX(Rosters!$N$2:$N$516,$S6)="","",INDEX(Rosters!$N$2:$N$516,$S6)),"") | Q6: =IFERROR(IF(INDEX(Rosters!$O$2:$O$516,$S6)="","",INDEX(Rosters!$O$2:$O$516,$S6)),"") | R6: =IFERROR(IF(INDEX(Rosters!$P$2:$P$516,$S6)="","",INDEX(Rosters!$P$2:$P$516,$S6)),"") | S6: =IFERROR(MATCH('League Settings'!$B$2&"|ACTIVE|"&3,Rosters!$AD$2:$AD$516,0),"") | T6: Tom Wilson (WSH RW) | U6: =IFERROR(IF(INDEX('Player Pool'!$D$2:$D$8725,MATCH($T6,'Player Pool'!$Z$2:$Z$8725,0))="","",INDEX('Player Pool'!$D$2:$D$8725,MATCH($T6,'Player Pool'!$Z$2:$Z$8725,0))),"") | V6: =IFERROR(IF(INDEX('Player Pool'!$E$2:$E$8725,MATCH($T6,'Player Pool'!$Z$2:$Z$8725,0))="","",INDEX('Player Pool'!$E$2:$E$8725,MATCH($T6,'Player Pool'!$Z$2:$Z$8725,0))),"") | W6: =IFERROR(IF($T6="","",IF(ISNUMBER(IFERROR(INDEX(Rosters!$I$2:$I$516,MATCH(INDEX('Player Pool'!$V$2:$V$8725,MATCH($T6,'Player Pool'!$Z$2:$Z$8725,0)),Rosters!$W$2:$W$516,0)),"")),IFERROR(INDEX(Rosters!$I$2:$I$516,MATCH(INDEX('Player Pool'!$V$2:$V$8725,MATCH($T6,'Player Pool'!$Z$2:$Z$8725,0)),Rosters!$W$2:$W$516,0)),""),INDEX('Player Pool'!$H$2:$H$8725,MATCH($T6,'Player Pool'!$Z$2:$Z$8725,0)))),"") | X6: =IFERROR(IF(INDEX('Player Pool'!$I$2:$I$8725,MATCH($T6,'Player Pool'!$Z$2:$Z$8725,0))="","",INDEX('Player Pool'!$I$2:$I$8725,MATCH($T6,'Player Pool'!$Z$2:$Z$8725,0))),"") | Y6: =IFERROR(IF(INDEX('Player Pool'!$P$2:$P$8725,MATCH($T6,'Player Pool'!$Z$2:$Z$8725,0))="","",INDEX('Player Pool'!$P$2:$P$8725,MATCH($T6,'Player Pool'!$Z$2:$Z$8725,0))),"") | Z6: =IFERROR(IF(INDEX('Player Pool'!$R$2:$R$8725,MATCH($T6,'Player Pool'!$Z$2:$Z$8725,0))="","",INDEX('Player Pool'!$R$2:$R$8725,MATCH($T6,'Player Pool'!$Z$2:$Z$8725,0))),"") | AA6: =IFERROR(IF(INDEX('Player Pool'!$U$2:$U$8725,MATCH($T6,'Player Pool'!$Z$2:$Z$8725,0))="","",INDEX('Player Pool'!$U$2:$U$8725,MATCH($T6,'Player Pool'!$Z$2:$Z$8725,0))),"") | AB6: =IFERROR(IF($T6="","",IF(INDEX('Player Pool'!$G$2:$G$8725,MATCH($T6,'Player Pool'!$Z$2:$Z$8725,0))="FA","FA",IF(INDEX('Player Pool'!$G$2:$G$8725,MATCH($T6,'Player Pool'!$Z$2:$Z$8725,0))='League Settings'!$B$2,"MINE","TAKEN"))),"") | AD6: Tom Wilson (WSH RW) | AE6: =IFERROR(IF(INDEX('Player Pool'!$D$2:$D$8725,MATCH($AD6,'Player Pool'!$Z$2:$Z$8725,0))="","",INDEX('Player Pool'!$D$2:$D$8725,MATCH($AD6,'Player Pool'!$Z$2:$Z$8725,0))),"") | AF6: =IFERROR(IF(INDEX('Player Pool'!$E$2:$E$8725,MATCH($AD6,'Player Pool'!$Z$2:$Z$8725,0))="","",INDEX('Player Pool'!$E$2:$E$8725,MATCH($AD6,'Player Pool'!$Z$2:$Z$8725,0))),"") | AG6: =IFERROR(IF($AD6="","",IF(ISNUMBER(IFERROR(INDEX(Rosters!$I$2:$I$516,MATCH(INDEX('Player Pool'!$V$2:$V$8725,MATCH($AD6,'Player Pool'!$Z$2:$Z$8725,0)),Rosters!$W$2:$W$516,0)),"")),IFERROR(INDEX(Rosters!$I$2:$I$516,MATCH(INDEX('Player Pool'!$V$2:$V$8725,MATCH($AD6,'Player Pool'!$Z$2:$Z$8725,0)),Rosters!$W$2:$W$516,0)),""),INDEX('Player Pool'!$H$2:$H$8725,MATCH($AD6,'Player Pool'!$Z$2:$Z$8725,0)))),"") | AH6: =IFERROR(IF(INDEX('Player Pool'!$I$2:$I$8725,MATCH($AD6,'Player Pool'!$Z$2:$Z$8725,0))="","",INDEX('Player Pool'!$I$2:$I$8725,MATCH($AD6,'Player Pool'!$Z$2:$Z$8725,0))),"") | AI6: =IFERROR(IF(INDEX('Player Pool'!$P$2:$P$8725,MATCH($AD6,'Player Pool'!$Z$2:$Z$8725,0))="","",INDEX('Player Pool'!$P$2:$P$8725,MATCH($AD6,'Player Pool'!$Z$2:$Z$8725,0))),"") | AJ6: =IFERROR(IF(INDEX('Player Pool'!$R$2:$R$8725,MATCH($AD6,'Player Pool'!$Z$2:$Z$8725,0))="","",INDEX('Player Pool'!$R$2:$R$8725,MATCH($AD6,'Player Pool'!$Z$2:$Z$8725,0))),"") | AK6: =IFERROR(IF(INDEX('Player Pool'!$U$2:$U$8725,MATCH($AD6,'Player Pool'!$Z$2:$Z$8725,0))="","",INDEX('Player Pool'!$U$2:$U$8725,MATCH($AD6,'Player Pool'!$Z$2:$Z$8725,0))),"") | AL6: =IFERROR(IF($AD6="","",IF(INDEX('Player Pool'!$G$2:$G$8725,MATCH($AD6,'Player Pool'!$Z$2:$Z$8725,0))="FA","FA",IF(INDEX('Player Pool'!$G$2:$G$8725,MATCH($AD6,'Player Pool'!$Z$2:$Z$8725,0))='League Settings'!$B$2,"MINE","TAKEN"))),"") | AN6: Tom Wilson (WSH RW) | AO6: =IFERROR(IF(INDEX('Player Pool'!$D$2:$D$8725,MATCH($AN6,'Player Pool'!$Z$2:$Z$8725,0))="","",INDEX('Player Pool'!$D$2:$D$8725,MATCH($AN6,'Player Pool'!$Z$2:$Z$8725,0))),"") | AP6: =IFERROR(IF(INDEX('Player Pool'!$E$2:$E$8725,MATCH($AN6,'Player Pool'!$Z$2:$Z$8725,0))="","",INDEX('Player Pool'!$E$2:$E$8725,MATCH($AN6,'Player Pool'!$Z$2:$Z$8725,0))),"") | AQ6: =IFERROR(IF($AN6="","",IF(ISNUMBER(IFERROR(INDEX(Rosters!$I$2:$I$516,MATCH(INDEX('Player Pool'!$V$2:$V$8725,MATCH($AN6,'Player Pool'!$Z$2:$Z$8725,0)),Rosters!$W$2:$W$516,0)),"")),IFERROR(INDEX(Rosters!$I$2:$I$516,MATCH(INDEX('Player Pool'!$V$2:$V$8725,MATCH($AN6,'Player Pool'!$Z$2:$Z$8725,0)),Rosters!$W$2:$W$516,0)),""),INDEX('Player Pool'!$H$2:$H$8725,MATCH($AN6,'Player Pool'!$Z$2:$Z$8725,0)))),"") | AR6: =IFERROR(IF(INDEX('Player Pool'!$I$2:$I$8725,MATCH($AN6,'Player Pool'!$Z$2:$Z$8725,0))="","",INDEX('Player Pool'!$I$2:$I$8725,MATCH($AN6,'Player Pool'!$Z$2:$Z$8725,0))),"") | AS6: =IFERROR(IF(INDEX('Player Pool'!$P$2:$P$8725,MATCH($AN6,'Player Pool'!$Z$2:$Z$8725,0))="","",INDEX('Player Pool'!$P$2:$P$8725,MATCH($AN6,'Player Pool'!$Z$2:$Z$8725,0))),"") | AT6: =IFERROR(IF(INDEX('Player Pool'!$R$2:$R$8725,MATCH($AN6,'Player Pool'!$Z$2:$Z$8725,0))="","",INDEX('Player Pool'!$R$2:$R$8725,MATCH($AN6,'Player Pool'!$Z$2:$Z$8725,0))),"") | AU6: =IFERROR(IF(INDEX('Player Pool'!$U$2:$U$8725,MATCH($AN6,'Player Pool'!$Z$2:$Z$8725,0))="","",INDEX('Player Pool'!$U$2:$U$8725,MATCH($AN6,'Player Pool'!$Z$2:$Z$8725,0))),"") | AV6: =IFERROR(IF($AN6="","",IF(INDEX('Player Pool'!$G$2:$G$8725,MATCH($AN6,'Player Pool'!$Z$2:$Z$8725,0))="FA","FA",IF(INDEX('Player Pool'!$G$2:$G$8725,MATCH($AN6,'Player Pool'!$Z$2:$Z$8725,0))='League Settings'!$B$2,"MINE","TAKEN"))),"")
A7: =IFERROR(IF(INDEX(Rosters!$B$2:$B$516,$S7)="","",INDEX(Rosters!$B$2:$B$516,$S7)),"") | B7: =IFERROR(IF(INDEX(Rosters!$C$2:$C$516,$S7)="","",INDEX(Rosters!$C$2:$C$516,$S7)),"") | C7: =IFERROR(IF(INDEX(Rosters!$D$2:$D$516,$S7)="","",INDEX(Rosters!$D$2:$D$516,$S7)),"") | D7: =IFERROR(IF(INDEX(Rosters!$E$2:$E$516,$S7)="","",INDEX(Rosters!$E$2:$E$516,$S7)),"") | E7: =IFERROR(IF(INDEX(Rosters!$F$2:$F$516,$S7)="","",INDEX(Rosters!$F$2:$F$516,$S7)),"") | F7: =IFERROR(IF(INDEX(Rosters!$G$2:$G$516,$S7)="","",INDEX(Rosters!$G$2:$G$516,$S7)),"") | G7: =IFERROR(IF(INDEX(Rosters!$H$2:$H$516,$S7)="","",INDEX(Rosters!$H$2:$H$516,$S7)),"") | H7: =IFERROR(IF(INDEX(Rosters!$I$2:$I$516,$S7)="","",INDEX(Rosters!$I$2:$I$516,$S7)),"") | I7: =IFERROR(IF(INDEX(Rosters!$J$2:$J$516,$S7)="","",INDEX(Rosters!$J$2:$J$516,$S7)),"") | J7: =IFERROR(IF(INDEX(Rosters!$S$2:$S$516,$S7)="","",INDEX(Rosters!$S$2:$S$516,$S7)),"") | K7: =IFERROR(IF(INDEX(Rosters!$K$2:$K$516,$S7)="","",INDEX(Rosters!$K$2:$K$516,$S7)),"") | L7: =IFERROR(IF(INDEX(Rosters!$T$2:$T$516,$S7)="","",INDEX(Rosters!$T$2:$T$516,$S7)),"") | M7: =IFERROR(IF(INDEX(Rosters!$L$2:$L$516,$S7)="","",INDEX(Rosters!$L$2:$L$516,$S7)),"") | N7: =IFERROR(IF(INDEX(Rosters!$Q$2:$Q$516,$S7)="","",INDEX(Rosters!$Q$2:$Q$516,$S7)),"") | O7: =IFERROR(IF(INDEX(Rosters!$R$2:$R$516,$S7)="","",INDEX(Rosters!$R$2:$R$516,$S7)),"") | P7: =IFERROR(IF(INDEX(Rosters!$N$2:$N$516,$S7)="","",INDEX(Rosters!$N$2:$N$516,$S7)),"") | Q7: =IFERROR(IF(INDEX(Rosters!$O$2:$O$516,$S7)="","",INDEX(Rosters!$O$2:$O$516,$S7)),"") | R7: =IFERROR(IF(INDEX(Rosters!$P$2:$P$516,$S7)="","",INDEX(Rosters!$P$2:$P$516,$S7)),"") | S7: =IFERROR(MATCH('League Settings'!$B$2&"|ACTIVE|"&4,Rosters!$AD$2:$AD$516,0),"") | T7: Karel Vejmelka (UTA G) | U7: =IFERROR(IF(INDEX('Player Pool'!$D$2:$D$8725,MATCH($T7,'Player Pool'!$Z$2:$Z$8725,0))="","",INDEX('Player Pool'!$D$2:$D$8725,MATCH($T7,'Player Pool'!$Z$2:$Z$8725,0))),"") | V7: =IFERROR(IF(INDEX('Player Pool'!$E$2:$E$8725,MATCH($T7,'Player Pool'!$Z$2:$Z$8725,0))="","",INDEX('Player Pool'!$E$2:$E$8725,MATCH($T7,'Player Pool'!$Z$2:$Z$8725,0))),"") | W7: =IFERROR(IF($T7="","",IF(ISNUMBER(IFERROR(INDEX(Rosters!$I$2:$I$516,MATCH(INDEX('Player Pool'!$V$2:$V$8725,MATCH($T7,'Player Pool'!$Z$2:$Z$8725,0)),Rosters!$W$2:$W$516,0)),"")),IFERROR(INDEX(Rosters!$I$2:$I$516,MATCH(INDEX('Player Pool'!$V$2:$V$8725,MATCH($T7,'Player Pool'!$Z$2:$Z$8725,0)),Rosters!$W$2:$W$516,0)),""),INDEX('Player Pool'!$H$2:$H$8725,MATCH($T7,'Player Pool'!$Z$2:$Z$8725,0)))),"") | X7: =IFERROR(IF(INDEX('Player Pool'!$I$2:$I$8725,MATCH($T7,'Player Pool'!$Z$2:$Z$8725,0))="","",INDEX('Player Pool'!$I$2:$I$8725,MATCH($T7,'Player Pool'!$Z$2:$Z$8725,0))),"") | Y7: =IFERROR(IF(INDEX('Player Pool'!$P$2:$P$8725,MATCH($T7,'Player Pool'!$Z$2:$Z$8725,0))="","",INDEX('Player Pool'!$P$2:$P$8725,MATCH($T7,'Player Pool'!$Z$2:$Z$8725,0))),"") | Z7: =IFERROR(IF(INDEX('Player Pool'!$R$2:$R$8725,MATCH($T7,'Player Pool'!$Z$2:$Z$8725,0))="","",INDEX('Player Pool'!$R$2:$R$8725,MATCH($T7,'Player Pool'!$Z$2:$Z$8725,0))),"") | AA7: =IFERROR(IF(INDEX('Player Pool'!$U$2:$U$8725,MATCH($T7,'Player Pool'!$Z$2:$Z$8725,0))="","",INDEX('Player Pool'!$U$2:$U$8725,MATCH($T7,'Player Pool'!$Z$2:$Z$8725,0))),"") | AB7: =IFERROR(IF($T7="","",IF(INDEX('Player Pool'!$G$2:$G$8725,MATCH($T7,'Player Pool'!$Z$2:$Z$8725,0))="FA","FA",IF(INDEX('Player Pool'!$G$2:$G$8725,MATCH($T7,'Player Pool'!$Z$2:$Z$8725,0))='League Settings'!$B$2,"MINE","TAKEN"))),"") | AD7: Karel Vejmelka (UTA G) | AE7: =IFERROR(IF(INDEX('Player Pool'!$D$2:$D$8725,MATCH($AD7,'Player Pool'!$Z$2:$Z$8725,0))="","",INDEX('Player Pool'!$D$2:$D$8725,MATCH($AD7,'Player Pool'!$Z$2:$Z$8725,0))),"") | AF7: =IFERROR(IF(INDEX('Player Pool'!$E$2:$E$8725,MATCH($AD7,'Player Pool'!$Z$2:$Z$8725,0))="","",INDEX('Player Pool'!$E$2:$E$8725,MATCH($AD7,'Player Pool'!$Z$2:$Z$8725,0))),"") | AG7: =IFERROR(IF($AD7="","",IF(ISNUMBER(IFERROR(INDEX(Rosters!$I$2:$I$516,MATCH(INDEX('Player Pool'!$V$2:$V$8725,MATCH($AD7,'Player Pool'!$Z$2:$Z$8725,0)),Rosters!$W$2:$W$516,0)),"")),IFERROR(INDEX(Rosters!$I$2:$I$516,MATCH(INDEX('Player Pool'!$V$2:$V$8725,MATCH($AD7,'Player Pool'!$Z$2:$Z$8725,0)),Rosters!$W$2:$W$516,0)),""),INDEX('Player Pool'!$H$2:$H$8725,MATCH($AD7,'Player Pool'!$Z$2:$Z$8725,0)))),"") | AH7: =IFERROR(IF(INDEX('Player Pool'!$I$2:$I$8725,MATCH($AD7,'Player Pool'!$Z$2:$Z$8725,0))="","",INDEX('Player Pool'!$I$2:$I$8725,MATCH($AD7,'Player Pool'!$Z$2:$Z$8725,0))),"") | AI7: =IFERROR(IF(INDEX('Player Pool'!$P$2:$P$8725,MATCH($AD7,'Player Pool'!$Z$2:$Z$8725,0))="","",INDEX('Player Pool'!$P$2:$P$8725,MATCH($AD7,'Player Pool'!$Z$2:$Z$8725,0))),"") | AJ7: =IFERROR(IF(INDEX('Player Pool'!$R$2:$R$8725,MATCH($AD7,'Player Pool'!$Z$2:$Z$8725,0))="","",INDEX('Player Pool'!$R$2:$R$8725,MATCH($AD7,'Player Pool'!$Z$2:$Z$8725,0))),"") | AK7: =IFERROR(IF(INDEX('Player Pool'!$U$2:$U$8725,MATCH($AD7,'Player Pool'!$Z$2:$Z$8725,0))="","",INDEX('Player Pool'!$U$2:$U$8725,MATCH($AD7,'Player Pool'!$Z$2:$Z$8725,0))),"") | AL7: =IFERROR(IF($AD7="","",IF(INDEX('Player Pool'!$G$2:$G$8725,MATCH($AD7,'Player Pool'!$Z$2:$Z$8725,0))="FA","FA",IF(INDEX('Player Pool'!$G$2:$G$8725,MATCH($AD7,'Player Pool'!$Z$2:$Z$8725,0))='League Settings'!$B$2,"MINE","TAKEN"))),"") | AN7: Karel Vejmelka (UTA G) | AO7: =IFERROR(IF(INDEX('Player Pool'!$D$2:$D$8725,MATCH($AN7,'Player Pool'!$Z$2:$Z$8725,0))="","",INDEX('Player Pool'!$D$2:$D$8725,MATCH($AN7,'Player Pool'!$Z$2:$Z$8725,0))),"") | AP7: =IFERROR(IF(INDEX('Player Pool'!$E$2:$E$8725,MATCH($AN7,'Player Pool'!$Z$2:$Z$8725,0))="","",INDEX('Player Pool'!$E$2:$E$8725,MATCH($AN7,'Player Pool'!$Z$2:$Z$8725,0))),"") | AQ7: =IFERROR(IF($AN7="","",IF(ISNUMBER(IFERROR(INDEX(Rosters!$I$2:$I$516,MATCH(INDEX('Player Pool'!$V$2:$V$8725,MATCH($AN7,'Player Pool'!$Z$2:$Z$8725,0)),Rosters!$W$2:$W$516,0)),"")),IFERROR(INDEX(Rosters!$I$2:$I$516,MATCH(INDEX('Player Pool'!$V$2:$V$8725,MATCH($AN7,'Player Pool'!$Z$2:$Z$8725,0)),Rosters!$W$2:$W$516,0)),""),INDEX('Player Pool'!$H$2:$H$8725,MATCH($AN7,'Player Pool'!$Z$2:$Z$8725,0)))),"") | AR7: =IFERROR(IF(INDEX('Player Pool'!$I$2:$I$8725,MATCH($AN7,'Player Pool'!$Z$2:$Z$8725,0))="","",INDEX('Player Pool'!$I$2:$I$8725,MATCH($AN7,'Player Pool'!$Z$2:$Z$8725,0))),"") | AS7: =IFERROR(IF(INDEX('Player Pool'!$P$2:$P$8725,MATCH($AN7,'Player Pool'!$Z$2:$Z$8725,0))="","",INDEX('Player Pool'!$P$2:$P$8725,MATCH($AN7,'Player Pool'!$Z$2:$Z$8725,0))),"") | AT7: =IFERROR(IF(INDEX('Player Pool'!$R$2:$R$8725,MATCH($AN7,'Player Pool'!$Z$2:$Z$8725,0))="","",INDEX('Player Pool'!$R$2:$R$8725,MATCH($AN7,'Player Pool'!$Z$2:$Z$8725,0))),"") | AU7: =IFERROR(IF(INDEX('Player Pool'!$U$2:$U$8725,MATCH($AN7,'Player Pool'!$Z$2:$Z$8725,0))="","",INDEX('Player Pool'!$U$2:$U$8725,MATCH($AN7,'Player Pool'!$Z$2:$Z$8725,0))),"") | AV7: =IFERROR(IF($AN7="","",IF(INDEX('Player Pool'!$G$2:$G$8725,MATCH($AN7,'Player Pool'!$Z$2:$Z$8725,0))="FA","FA",IF(INDEX('Player Pool'!$G$2:$G$8725,MATCH($AN7,'Player Pool'!$Z$2:$Z$8725,0))='League Settings'!$B$2,"MINE","TAKEN"))),"")
A8: =IFERROR(IF(INDEX(Rosters!$B$2:$B$516,$S8)="","",INDEX(Rosters!$B$2:$B$516,$S8)),"") | B8: =IFERROR(IF(INDEX(Rosters!$C$2:$C$516,$S8)="","",INDEX(Rosters!$C$2:$C$516,$S8)),"") | C8: =IFERROR(IF(INDEX(Rosters!$D$2:$D$516,$S8)="","",INDEX(Rosters!$D$2:$D$516,$S8)),"") | D8: =IFERROR(IF(INDEX(Rosters!$E$2:$E$516,$S8)="","",INDEX(Rosters!$E$2:$E$516,$S8)),"") | E8: =IFERROR(IF(INDEX(Rosters!$F$2:$F$516,$S8)="","",INDEX(Rosters!$F$2:$F$516,$S8)),"") | F8: =IFERROR(IF(INDEX(Rosters!$G$2:$G$516,$S8)="","",INDEX(Rosters!$G$2:$G$516,$S8)),"") | G8: =IFERROR(IF(INDEX(Rosters!$H$2:$H$516,$S8)="","",INDEX(Rosters!$H$2:$H$516,$S8)),"") | H8: =IFERROR(IF(INDEX(Rosters!$I$2:$I$516,$S8)="","",INDEX(Rosters!$I$2:$I$516,$S8)),"") | I8: =IFERROR(IF(INDEX(Rosters!$J$2:$J$516,$S8)="","",INDEX(Rosters!$J$2:$J$516,$S8)),"") | J8: =IFERROR(IF(INDEX(Rosters!$S$2:$S$516,$S8)="","",INDEX(Rosters!$S$2:$S$516,$S8)),"") | K8: =IFERROR(IF(INDEX(Rosters!$K$2:$K$516,$S8)="","",INDEX(Rosters!$K$2:$K$516,$S8)),"") | L8: =IFERROR(IF(INDEX(Rosters!$T$2:$T$516,$S8)="","",INDEX(Rosters!$T$2:$T$516,$S8)),"") | M8: =IFERROR(IF(INDEX(Rosters!$L$2:$L$516,$S8)="","",INDEX(Rosters!$L$2:$L$516,$S8)),"") | N8: =IFERROR(IF(INDEX(Rosters!$Q$2:$Q$516,$S8)="","",INDEX(Rosters!$Q$2:$Q$516,$S8)),"") | O8: =IFERROR(IF(INDEX(Rosters!$R$2:$R$516,$S8)="","",INDEX(Rosters!$R$2:$R$516,$S8)),"") | P8: =IFERROR(IF(INDEX(Rosters!$N$2:$N$516,$S8)="","",INDEX(Rosters!$N$2:$N$516,$S8)),"") | Q8: =IFERROR(IF(INDEX(Rosters!$O$2:$O$516,$S8)="","",INDEX(Rosters!$O$2:$O$516,$S8)),"") | R8: =IFERROR(IF(INDEX(Rosters!$P$2:$P$516,$S8)="","",INDEX(Rosters!$P$2:$P$516,$S8)),"") | S8: =IFERROR(MATCH('League Settings'!$B$2&"|ACTIVE|"&5,Rosters!$AD$2:$AD$516,0),"") | T8: Sebastian Aho (CAR C) | U8: =IFERROR(IF(INDEX('Player Pool'!$D$2:$D$8725,MATCH($T8,'Player Pool'!$Z$2:$Z$8725,0))="","",INDEX('Player Pool'!$D$2:$D$8725,MATCH($T8,'Player Pool'!$Z$2:$Z$8725,0))),"") | V8: =IFERROR(IF(INDEX('Player Pool'!$E$2:$E$8725,MATCH($T8,'Player Pool'!$Z$2:$Z$8725,0))="","",INDEX('Player Pool'!$E$2:$E$8725,MATCH($T8,'Player Pool'!$Z$2:$Z$8725,0))),"") | W8: =IFERROR(IF($T8="","",IF(ISNUMBER(IFERROR(INDEX(Rosters!$I$2:$I$516,MATCH(INDEX('Player Pool'!$V$2:$V$8725,MATCH($T8,'Player Pool'!$Z$2:$Z$8725,0)),Rosters!$W$2:$W$516,0)),"")),IFERROR(INDEX(Rosters!$I$2:$I$516,MATCH(INDEX('Player Pool'!$V$2:$V$8725,MATCH($T8,'Player Pool'!$Z$2:$Z$8725,0)),Rosters!$W$2:$W$516,0)),""),INDEX('Player Pool'!$H$2:$H$8725,MATCH($T8,'Player Pool'!$Z$2:$Z$8725,0)))),"") | X8: =IFERROR(IF(INDEX('Player Pool'!$I$2:$I$8725,MATCH($T8,'Player Pool'!$Z$2:$Z$8725,0))="","",INDEX('Player Pool'!$I$2:$I$8725,MATCH($T8,'Player Pool'!$Z$2:$Z$8725,0))),"") | Y8: =IFERROR(IF(INDEX('Player Pool'!$P$2:$P$8725,MATCH($T8,'Player Pool'!$Z$2:$Z$8725,0))="","",INDEX('Player Pool'!$P$2:$P$8725,MATCH($T8,'Player Pool'!$Z$2:$Z$8725,0))),"") | Z8: =IFERROR(IF(INDEX('Player Pool'!$R$2:$R$8725,MATCH($T8,'Player Pool'!$Z$2:$Z$8725,0))="","",INDEX('Player Pool'!$R$2:$R$8725,MATCH($T8,'Player Pool'!$Z$2:$Z$8725,0))),"") | AA8: =IFERROR(IF(INDEX('Player Pool'!$U$2:$U$8725,MATCH($T8,'Player Pool'!$Z$2:$Z$8725,0))="","",INDEX('Player Pool'!$U$2:$U$8725,MATCH($T8,'Player Pool'!$Z$2:$Z$8725,0))),"") | AB8: =IFERROR(IF($T8="","",IF(INDEX('Player Pool'!$G$2:$G$8725,MATCH($T8,'Player Pool'!$Z$2:$Z$8725,0))="FA","FA",IF(INDEX('Player Pool'!$G$2:$G$8725,MATCH($T8,'Player Pool'!$Z$2:$Z$8725,0))='League Settings'!$B$2,"MINE","TAKEN"))),"") | AD8: Sebastian Aho (CAR C) | AE8: =IFERROR(IF(INDEX('Player Pool'!$D$2:$D$8725,MATCH($AD8,'Player Pool'!$Z$2:$Z$8725,0))="","",INDEX('Player Pool'!$D$2:$D$8725,MATCH($AD8,'Player Pool'!$Z$2:$Z$8725,0))),"") | AF8: =IFERROR(IF(INDEX('Player Pool'!$E$2:$E$8725,MATCH($AD8,'Player Pool'!$Z$2:$Z$8725,0))="","",INDEX('Player Pool'!$E$2:$E$8725,MATCH($AD8,'Player Pool'!$Z$2:$Z$8725,0))),"") | AG8: =IFERROR(IF($AD8="","",IF(ISNUMBER(IFERROR(INDEX(Rosters!$I$2:$I$516,MATCH(INDEX('Player Pool'!$V$2:$V$8725,MATCH($AD8,'Player Pool'!$Z$2:$Z$8725,0)),Rosters!$W$2:$W$516,0)),"")),IFERROR(INDEX(Rosters!$I$2:$I$516,MATCH(INDEX('Player Pool'!$V$2:$V$8725,MATCH($AD8,'Player Pool'!$Z$2:$Z$8725,0)),Rosters!$W$2:$W$516,0)),""),INDEX('Player Pool'!$H$2:$H$8725,MATCH($AD8,'Player Pool'!$Z$2:$Z$8725,0)))),"") | AH8: =IFERROR(IF(INDEX('Player Pool'!$I$2:$I$8725,MATCH($AD8,'Player Pool'!$Z$2:$Z$8725,0))="","",INDEX('Player Pool'!$I$2:$I$8725,MATCH($AD8,'Player Pool'!$Z$2:$Z$8725,0))),"") | AI8: =IFERROR(IF(INDEX('Player Pool'!$P$2:$P$8725,MATCH($AD8,'Player Pool'!$Z$2:$Z$8725,0))="","",INDEX('Player Pool'!$P$2:$P$8725,MATCH($AD8,'Player Pool'!$Z$2:$Z$8725,0))),"") | AJ8: =IFERROR(IF(INDEX('Player Pool'!$R$2:$R$8725,MATCH($AD8,'Player Pool'!$Z$2:$Z$8725,0))="","",INDEX('Player Pool'!$R$2:$R$8725,MATCH($AD8,'Player Pool'!$Z$2:$Z$8725,0))),"") | AK8: =IFERROR(IF(INDEX('Player Pool'!$U$2:$U$8725,MATCH($AD8,'Player Pool'!$Z$2:$Z$8725,0))="","",INDEX('Player Pool'!$U$2:$U$8725,MATCH($AD8,'Player Pool'!$Z$2:$Z$8725,0))),"") | AL8: =IFERROR(IF($AD8="","",IF(INDEX('Player Pool'!$G$2:$G$8725,MATCH($AD8,'Player Pool'!$Z$2:$Z$8725,0))="FA","FA",IF(INDEX('Player Pool'!$G$2:$G$8725,MATCH($AD8,'Player Pool'!$Z$2:$Z$8725,0))='League Settings'!$B$2,"MINE","TAKEN"))),"") | AN8: Sebastian Aho (CAR C) | AO8: =IFERROR(IF(INDEX('Player Pool'!$D$2:$D$8725,MATCH($AN8,'Player Pool'!$Z$2:$Z$8725,0))="","",INDEX('Player Pool'!$D$2:$D$8725,MATCH($AN8,'Player Pool'!$Z$2:$Z$8725,0))),"") | AP8: =IFERROR(IF(INDEX('Player Pool'!$E$2:$E$8725,MATCH($AN8,'Player Pool'!$Z$2:$Z$8725,0))="","",INDEX('Player Pool'!$E$2:$E$8725,MATCH($AN8,'Player Pool'!$Z$2:$Z$8725,0))),"") | AQ8: =IFERROR(IF($AN8="","",IF(ISNUMBER(IFERROR(INDEX(Rosters!$I$2:$I$516,MATCH(INDEX('Player Pool'!$V$2:$V$8725,MATCH($AN8,'Player Pool'!$Z$2:$Z$8725,0)),Rosters!$W$2:$W$516,0)),"")),IFERROR(INDEX(Rosters!$I$2:$I$516,MATCH(INDEX('Player Pool'!$V$2:$V$8725,MATCH($AN8,'Player Pool'!$Z$2:$Z$8725,0)),Rosters!$W$2:$W$516,0)),""),INDEX('Player Pool'!$H$2:$H$8725,MATCH($AN8,'Player Pool'!$Z$2:$Z$8725,0)))),"") | AR8: =IFERROR(IF(INDEX('Player Pool'!$I$2:$I$8725,MATCH($AN8,'Player Pool'!$Z$2:$Z$8725,0))="","",INDEX('Player Pool'!$I$2:$I$8725,MATCH($AN8,'Player Pool'!$Z$2:$Z$8725,0))),"") | AS8: =IFERROR(IF(INDEX('Player Pool'!$P$2:$P$8725,MATCH($AN8,'Player Pool'!$Z$2:$Z$8725,0))="","",INDEX('Player Pool'!$P$2:$P$8725,MATCH($AN8,'Player Pool'!$Z$2:$Z$8725,0))),"") | AT8: =IFERROR(IF(INDEX('Player Pool'!$R$2:$R$8725,MATCH($AN8,'Player Pool'!$Z$2:$Z$8725,0))="","",INDEX('Player Pool'!$R$2:$R$8725,MATCH($AN8,'Player Pool'!$Z$2:$Z$8725,0))),"") | AU8: =IFERROR(IF(INDEX('Player Pool'!$U$2:$U$8725,MATCH($AN8,'Player Pool'!$Z$2:$Z$8725,0))="","",INDEX('Player Pool'!$U$2:$U$8725,MATCH($AN8,'Player Pool'!$Z$2:$Z$8725,0))),"") | AV8: =IFERROR(IF($AN8="","",IF(INDEX('Player Pool'!$G$2:$G$8725,MATCH($AN8,'Player Pool'!$Z$2:$Z$8725,0))="FA","FA",IF(INDEX('Player Pool'!$G$2:$G$8725,MATCH($AN8,'Player Pool'!$Z$2:$Z$8725,0))='League Settings'!$B$2,"MINE","TAKEN"))),"")
A9: =IFERROR(IF(INDEX(Rosters!$B$2:$B$516,$S9)="","",INDEX(Rosters!$B$2:$B$516,$S9)),"") | B9: =IFERROR(IF(INDEX(Rosters!$C$2:$C$516,$S9)="","",INDEX(Rosters!$C$2:$C$516,$S9)),"") | C9: =IFERROR(IF(INDEX(Rosters!$D$2:$D$516,$S9)="","",INDEX(Rosters!$D$2:$D$516,$S9)),"") | D9: =IFERROR(IF(INDEX(Rosters!$E$2:$E$516,$S9)="","",INDEX(Rosters!$E$2:$E$516,$S9)),"") | E9: =IFERROR(IF(INDEX(Rosters!$F$2:$F$516,$S9)="","",INDEX(Rosters!$F$2:$F$516,$S9)),"") | F9: =IFERROR(IF(INDEX(Rosters!$G$2:$G$516,$S9)="","",INDEX(Rosters!$G$2:$G$516,$S9)),"") | G9: =IFERROR(IF(INDEX(Rosters!$H$2:$H$516,$S9)="","",INDEX(Rosters!$H$2:$H$516,$S9)),"") | H9: =IFERROR(IF(INDEX(Rosters!$I$2:$I$516,$S9)="","",INDEX(Rosters!$I$2:$I$516,$S9)),"") | I9: =IFERROR(IF(INDEX(Rosters!$J$2:$J$516,$S9)="","",INDEX(Rosters!$J$2:$J$516,$S9)),"") | J9: =IFERROR(IF(INDEX(Rosters!$S$2:$S$516,$S9)="","",INDEX(Rosters!$S$2:$S$516,$S9)),"") | K9: =IFERROR(IF(INDEX(Rosters!$K$2:$K$516,$S9)="","",INDEX(Rosters!$K$2:$K$516,$S9)),"") | L9: =IFERROR(IF(INDEX(Rosters!$T$2:$T$516,$S9)="","",INDEX(Rosters!$T$2:$T$516,$S9)),"") | M9: =IFERROR(IF(INDEX(Rosters!$L$2:$L$516,$S9)="","",INDEX(Rosters!$L$2:$L$516,$S9)),"") | N9: =IFERROR(IF(INDEX(Rosters!$Q$2:$Q$516,$S9)="","",INDEX(Rosters!$Q$2:$Q$516,$S9)),"") | O9: =IFERROR(IF(INDEX(Rosters!$R$2:$R$516,$S9)="","",INDEX(Rosters!$R$2:$R$516,$S9)),"") | P9: =IFERROR(IF(INDEX(Rosters!$N$2:$N$516,$S9)="","",INDEX(Rosters!$N$2:$N$516,$S9)),"") | Q9: =IFERROR(IF(INDEX(Rosters!$O$2:$O$516,$S9)="","",INDEX(Rosters!$O$2:$O$516,$S9)),"") | R9: =IFERROR(IF(INDEX(Rosters!$P$2:$P$516,$S9)="","",INDEX(Rosters!$P$2:$P$516,$S9)),"") | S9: =IFERROR(MATCH('League Settings'!$B$2&"|ACTIVE|"&6,Rosters!$AD$2:$AD$516,0),"") | T9: Josh Morrissey (WPG D) | U9: =IFERROR(IF(INDEX('Player Pool'!$D$2:$D$8725,MATCH($T9,'Player Pool'!$Z$2:$Z$8725,0))="","",INDEX('Player Pool'!$D$2:$D$8725,MATCH($T9,'Player Pool'!$Z$2:$Z$8725,0))),"") | V9: =IFERROR(IF(INDEX('Player Pool'!$E$2:$E$8725,MATCH($T9,'Player Pool'!$Z$2:$Z$8725,0))="","",INDEX('Player Pool'!$E$2:$E$8725,MATCH($T9,'Player Pool'!$Z$2:$Z$8725,0))),"") | W9: =IFERROR(IF($T9="","",IF(ISNUMBER(IFERROR(INDEX(Rosters!$I$2:$I$516,MATCH(INDEX('Player Pool'!$V$2:$V$8725,MATCH($T9,'Player Pool'!$Z$2:$Z$8725,0)),Rosters!$W$2:$W$516,0)),"")),IFERROR(INDEX(Rosters!$I$2:$I$516,MATCH(INDEX('Player Pool'!$V$2:$V$8725,MATCH($T9,'Player Pool'!$Z$2:$Z$8725,0)),Rosters!$W$2:$W$516,0)),""),INDEX('Player Pool'!$H$2:$H$8725,MATCH($T9,'Player Pool'!$Z$2:$Z$8725,0)))),"") | X9: =IFERROR(IF(INDEX('Player Pool'!$I$2:$I$8725,MATCH($T9,'Player Pool'!$Z$2:$Z$8725,0))="","",INDEX('Player Pool'!$I$2:$I$8725,MATCH($T9,'Player Pool'!$Z$2:$Z$8725,0))),"") | Y9: =IFERROR(IF(INDEX('Player Pool'!$P$2:$P$8725,MATCH($T9,'Player Pool'!$Z$2:$Z$8725,0))="","",INDEX('Player Pool'!$P$2:$P$8725,MATCH($T9,'Player Pool'!$Z$2:$Z$8725,0))),"") | Z9: =IFERROR(IF(INDEX('Player Pool'!$R$2:$R$8725,MATCH($T9,'Player Pool'!$Z$2:$Z$8725,0))="","",INDEX('Player Pool'!$R$2:$R$8725,MATCH($T9,'Player Pool'!$Z$2:$Z$8725,0))),"") | AA9: =IFERROR(IF(INDEX('Player Pool'!$U$2:$U$8725,MATCH($T9,'Player Pool'!$Z$2:$Z$8725,0))="","",INDEX('Player Pool'!$U$2:$U$8725,MATCH($T9,'Player Pool'!$Z$2:$Z$8725,0))),"") | AB9: =IFERROR(IF($T9="","",IF(INDEX('Player Pool'!$G$2:$G$8725,MATCH($T9,'Player Pool'!$Z$2:$Z$8725,0))="FA","FA",IF(INDEX('Player Pool'!$G$2:$G$8725,MATCH($T9,'Player Pool'!$Z$2:$Z$8725,0))='League Settings'!$B$2,"MINE","TAKEN"))),"") | AD9: Josh Morrissey (WPG D) | AE9: =IFERROR(IF(INDEX('Player Pool'!$D$2:$D$8725,MATCH($AD9,'Player Pool'!$Z$2:$Z$8725,0))="","",INDEX('Player Pool'!$D$2:$D$8725,MATCH($AD9,'Player Pool'!$Z$2:$Z$8725,0))),"") | AF9: =IFERROR(IF(INDEX('Player Pool'!$E$2:$E$8725,MATCH($AD9,'Player Pool'!$Z$2:$Z$8725,0))="","",INDEX('Player Pool'!$E$2:$E$8725,MATCH($AD9,'Player Pool'!$Z$2:$Z$8725,0))),"") | AG9: =IFERROR(IF($AD9="","",IF(ISNUMBER(IFERROR(INDEX(Rosters!$I$2:$I$516,MATCH(INDEX('Player Pool'!$V$2:$V$8725,MATCH($AD9,'Player Pool'!$Z$2:$Z$8725,0)),Rosters!$W$2:$W$516,0)),"")),IFERROR(INDEX(Rosters!$I$2:$I$516,MATCH(INDEX('Player Pool'!$V$2:$V$8725,MATCH($AD9,'Player Pool'!$Z$2:$Z$8725,0)),Rosters!$W$2:$W$516,0)),""),INDEX('Player Pool'!$H$2:$H$8725,MATCH($AD9,'Player Pool'!$Z$2:$Z$8725,0)))),"") | AH9: =IFERROR(IF(INDEX('Player Pool'!$I$2:$I$8725,MATCH($AD9,'Player Pool'!$Z$2:$Z$8725,0))="","",INDEX('Player Pool'!$I$2:$I$8725,MATCH($AD9,'Player Pool'!$Z$2:$Z$8725,0))),"") | AI9: =IFERROR(IF(INDEX('Player Pool'!$P$2:$P$8725,MATCH($AD9,'Player Pool'!$Z$2:$Z$8725,0))="","",INDEX('Player Pool'!$P$2:$P$8725,MATCH($AD9,'Player Pool'!$Z$2:$Z$8725,0))),"") | AJ9: =IFERROR(IF(INDEX('Player Pool'!$R$2:$R$8725,MATCH($AD9,'Player Pool'!$Z$2:$Z$8725,0))="","",INDEX('Player Pool'!$R$2:$R$8725,MATCH($AD9,'Player Pool'!$Z$2:$Z$8725,0))),"") | AK9: =IFERROR(IF(INDEX('Player Pool'!$U$2:$U$8725,MATCH($AD9,'Player Pool'!$Z$2:$Z$8725,0))="","",INDEX('Player Pool'!$U$2:$U$8725,MATCH($AD9,'Player Pool'!$Z$2:$Z$8725,0))),"") | AL9: =IFERROR(IF($AD9="","",IF(INDEX('Player Pool'!$G$2:$G$8725,MATCH($AD9,'Player Pool'!$Z$2:$Z$8725,0))="FA","FA",IF(INDEX('Player Pool'!$G$2:$G$8725,MATCH($AD9,'Player Pool'!$Z$2:$Z$8725,0))='League Settings'!$B$2,"MINE","TAKEN"))),"") | AN9: Josh Morrissey (WPG D) | AO9: =IFERROR(IF(INDEX('Player Pool'!$D$2:$D$8725,MATCH($AN9,'Player Pool'!$Z$2:$Z$8725,0))="","",INDEX('Player Pool'!$D$2:$D$8725,MATCH($AN9,'Player Pool'!$Z$2:$Z$8725,0))),"") | AP9: =IFERROR(IF(INDEX('Player Pool'!$E$2:$E$8725,MATCH($AN9,'Player Pool'!$Z$2:$Z$8725,0))="","",INDEX('Player Pool'!$E$2:$E$8725,MATCH($AN9,'Player Pool'!$Z$2:$Z$8725,0))),"") | AQ9: =IFERROR(IF($AN9="","",IF(ISNUMBER(IFERROR(INDEX(Rosters!$I$2:$I$516,MATCH(INDEX('Player Pool'!$V$2:$V$8725,MATCH($AN9,'Player Pool'!$Z$2:$Z$8725,0)),Rosters!$W$2:$W$516,0)),"")),IFERROR(INDEX(Rosters!$I$2:$I$516,MATCH(INDEX('Player Pool'!$V$2:$V$8725,MATCH($AN9,'Player Pool'!$Z$2:$Z$8725,0)),Rosters!$W$2:$W$516,0)),""),INDEX('Player Pool'!$H$2:$H$8725,MATCH($AN9,'Player Pool'!$Z$2:$Z$8725,0)))),"") | AR9: =IFERROR(IF(INDEX('Player Pool'!$I$2:$I$8725,MATCH($AN9,'Player Pool'!$Z$2:$Z$8725,0))="","",INDEX('Player Pool'!$I$2:$I$8725,MATCH($AN9,'Player Pool'!$Z$2:$Z$8725,0))),"") | AS9: =IFERROR(IF(INDEX('Player Pool'!$P$2:$P$8725,MATCH($AN9,'Player Pool'!$Z$2:$Z$8725,0))="","",INDEX('Player Pool'!$P$2:$P$8725,MATCH($AN9,'Player Pool'!$Z$2:$Z$8725,0))),"") | AT9: =IFERROR(IF(INDEX('Player Pool'!$R$2:$R$8725,MATCH($AN9,'Player Pool'!$Z$2:$Z$8725,0))="","",INDEX('Player Pool'!$R$2:$R$8725,MATCH($AN9,'Player Pool'!$Z$2:$Z$8725,0))),"") | AU9: =IFERROR(IF(INDEX('Player Pool'!$U$2:$U$8725,MATCH($AN9,'Player Pool'!$Z$2:$Z$8725,0))="","",INDEX('Player Pool'!$U$2:$U$8725,MATCH($AN9,'Player Pool'!$Z$2:$Z$8725,0))),"") | AV9: =IFERROR(IF($AN9="","",IF(INDEX('Player Pool'!$G$2:$G$8725,MATCH($AN9,'Player Pool'!$Z$2:$Z$8725,0))="FA","FA",IF(INDEX('Player Pool'!$G$2:$G$8725,MATCH($AN9,'Player Pool'!$Z$2:$Z$8725,0))='League Settings'!$B$2,"MINE","TAKEN"))),"")
A10: =IFERROR(IF(INDEX(Rosters!$B$2:$B$516,$S10)="","",INDEX(Rosters!$B$2:$B$516,$S10)),"") | B10: =IFERROR(IF(INDEX(Rosters!$C$2:$C$516,$S10)="","",INDEX(Rosters!$C$2:$C$516,$S10)),"") | C10: =IFERROR(IF(INDEX(Rosters!$D$2:$D$516,$S10)="","",INDEX(Rosters!$D$2:$D$516,$S10)),"") | D10: =IFERROR(IF(INDEX(Rosters!$E$2:$E$516,$S10)="","",INDEX(Rosters!$E$2:$E$516,$S10)),"") | E10: =IFERROR(IF(INDEX(Rosters!$F$2:$F$516,$S10)="","",INDEX(Rosters!$F$2:$F$516,$S10)),"") | F10: =IFERROR(IF(INDEX(Rosters!$G$2:$G$516,$S10)="","",INDEX(Rosters!$G$2:$G$516,$S10)),"") | G10: =IFERROR(IF(INDEX(Rosters!$H$2:$H$516,$S10)="","",INDEX(Rosters!$H$2:$H$516,$S10)),"") | H10: =IFERROR(IF(INDEX(Rosters!$I$2:$I$516,$S10)="","",INDEX(Rosters!$I$2:$I$516,$S10)),"") | I10: =IFERROR(IF(INDEX(Rosters!$J$2:$J$516,$S10)="","",INDEX(Rosters!$J$2:$J$516,$S10)),"") | J10: =IFERROR(IF(INDEX(Rosters!$S$2:$S$516,$S10)="","",INDEX(Rosters!$S$2:$S$516,$S10)),"") | K10: =IFERROR(IF(INDEX(Rosters!$K$2:$K$516,$S10)="","",INDEX(Rosters!$K$2:$K$516,$S10)),"") | L10: =IFERROR(IF(INDEX(Rosters!$T$2:$T$516,$S10)="","",INDEX(Rosters!$T$2:$T$516,$S10)),"") | M10: =IFERROR(IF(INDEX(Rosters!$L$2:$L$516,$S10)="","",INDEX(Rosters!$L$2:$L$516,$S10)),"") | N10: =IFERROR(IF(INDEX(Rosters!$Q$2:$Q$516,$S10)="","",INDEX(Rosters!$Q$2:$Q$516,$S10)),"") | O10: =IFERROR(IF(INDEX(Rosters!$R$2:$R$516,$S10)="","",INDEX(Rosters!$R$2:$R$516,$S10)),"") | P10: =IFERROR(IF(INDEX(Rosters!$N$2:$N$516,$S10)="","",INDEX(Rosters!$N$2:$N$516,$S10)),"") | Q10: =IFERROR(IF(INDEX(Rosters!$O$2:$O$516,$S10)="","",INDEX(Rosters!$O$2:$O$516,$S10)),"") | R10: =IFERROR(IF(INDEX(Rosters!$P$2:$P$516,$S10)="","",INDEX(Rosters!$P$2:$P$516,$S10)),"") | S10: =IFERROR(MATCH('League Settings'!$B$2&"|ACTIVE|"&7,Rosters!$AD$2:$AD$516,0),"") | T10: Jackson LaCombe (ANA D) | U10: =IFERROR(IF(INDEX('Player Pool'!$D$2:$D$8725,MATCH($T10,'Player Pool'!$Z$2:$Z$8725,0))="","",INDEX('Player Pool'!$D$2:$D$8725,MATCH($T10,'Player Pool'!$Z$2:$Z$8725,0))),"") | V10: =IFERROR(IF(INDEX('Player Pool'!$E$2:$E$8725,MATCH($T10,'Player Pool'!$Z$2:$Z$8725,0))="","",INDEX('Player Pool'!$E$2:$E$8725,MATCH($T10,'Player Pool'!$Z$2:$Z$8725,0))),"") | W10: =IFERROR(IF($T10="","",IF(ISNUMBER(IFERROR(INDEX(Rosters!$I$2:$I$516,MATCH(INDEX('Player Pool'!$V$2:$V$8725,MATCH($T10,'Player Pool'!$Z$2:$Z$8725,0)),Rosters!$W$2:$W$516,0)),"")),IFERROR(INDEX(Rosters!$I$2:$I$516,MATCH(INDEX('Player Pool'!$V$2:$V$8725,MATCH($T10,'Player Pool'!$Z$2:$Z$8725,0)),Rosters!$W$2:$W$516,0)),""),INDEX('Player Pool'!$H$2:$H$8725,MATCH($T10,'Player Pool'!$Z$2:$Z$8725,0)))),"") | X10: =IFERROR(IF(INDEX('Player Pool'!$I$2:$I$8725,MATCH($T10,'Player Pool'!$Z$2:$Z$8725,0))="","",INDEX('Player Pool'!$I$2:$I$8725,MATCH($T10,'Player Pool'!$Z$2:$Z$8725,0))),"") | Y10: =IFERROR(IF(INDEX('Player Pool'!$P$2:$P$8725,MATCH($T10,'Player Pool'!$Z$2:$Z$8725,0))="","",INDEX('Player Pool'!$P$2:$P$8725,MATCH($T10,'Player Pool'!$Z$2:$Z$8725,0))),"") | Z10: =IFERROR(IF(INDEX('Player Pool'!$R$2:$R$8725,MATCH($T10,'Player Pool'!$Z$2:$Z$8725,0))="","",INDEX('Player Pool'!$R$2:$R$8725,MATCH($T10,'Player Pool'!$Z$2:$Z$8725,0))),"") | AA10: =IFERROR(IF(INDEX('Player Pool'!$U$2:$U$8725,MATCH($T10,'Player Pool'!$Z$2:$Z$8725,0))="","",INDEX('Player Pool'!$U$2:$U$8725,MATCH($T10,'Player Pool'!$Z$2:$Z$8725,0))),"") | AB10: =IFERROR(IF($T10="","",IF(INDEX('Player Pool'!$G$2:$G$8725,MATCH($T10,'Player Pool'!$Z$2:$Z$8725,0))="FA","FA",IF(INDEX('Player Pool'!$G$2:$G$8725,MATCH($T10,'Player Pool'!$Z$2:$Z$8725,0))='League Settings'!$B$2,"MINE","TAKEN"))),"") | AD10: Jackson LaCombe (ANA D) | AE10: =IFERROR(IF(INDEX('Player Pool'!$D$2:$D$8725,MATCH($AD10,'Player Pool'!$Z$2:$Z$8725,0))="","",INDEX('Player Pool'!$D$2:$D$8725,MATCH($AD10,'Player Pool'!$Z$2:$Z$8725,0))),"") | AF10: =IFERROR(IF(INDEX('Player Pool'!$E$2:$E$8725,MATCH($AD10,'Player Pool'!$Z$2:$Z$8725,0))="","",INDEX('Player Pool'!$E$2:$E$8725,MATCH($AD10,'Player Pool'!$Z$2:$Z$8725,0))),"") | AG10: =IFERROR(IF($AD10="","",IF(ISNUMBER(IFERROR(INDEX(Rosters!$I$2:$I$516,MATCH(INDEX('Player Pool'!$V$2:$V$8725,MATCH($AD10,'Player Pool'!$Z$2:$Z$8725,0)),Rosters!$W$2:$W$516,0)),"")),IFERROR(INDEX(Rosters!$I$2:$I$516,MATCH(INDEX('Player Pool'!$V$2:$V$8725,MATCH($AD10,'Player Pool'!$Z$2:$Z$8725,0)),Rosters!$W$2:$W$516,0)),""),INDEX('Player Pool'!$H$2:$H$8725,MATCH($AD10,'Player Pool'!$Z$2:$Z$8725,0)))),"") | AH10: =IFERROR(IF(INDEX('Player Pool'!$I$2:$I$8725,MATCH($AD10,'Player Pool'!$Z$2:$Z$8725,0))="","",INDEX('Player Pool'!$I$2:$I$8725,MATCH($AD10,'Player Pool'!$Z$2:$Z$8725,0))),"") | AI10: =IFERROR(IF(INDEX('Player Pool'!$P$2:$P$8725,MATCH($AD10,'Player Pool'!$Z$2:$Z$8725,0))="","",INDEX('Player Pool'!$P$2:$P$8725,MATCH($AD10,'Player Pool'!$Z$2:$Z$8725,0))),"") | AJ10: =IFERROR(IF(INDEX('Player Pool'!$R$2:$R$8725,MATCH($AD10,'Player Pool'!$Z$2:$Z$8725,0))="","",INDEX('Player Pool'!$R$2:$R$8725,MATCH($AD10,'Player Pool'!$Z$2:$Z$8725,0))),"") | AK10: =IFERROR(IF(INDEX('Player Pool'!$U$2:$U$8725,MATCH($AD10,'Player Pool'!$Z$2:$Z$8725,0))="","",INDEX('Player Pool'!$U$2:$U$8725,MATCH($AD10,'Player Pool'!$Z$2:$Z$8725,0))),"") | AL10: =IFERROR(IF($AD10="","",IF(INDEX('Player Pool'!$G$2:$G$8725,MATCH($AD10,'Player Pool'!$Z$2:$Z$8725,0))="FA","FA",IF(INDEX('Player Pool'!$G$2:$G$8725,MATCH($AD10,'Player Pool'!$Z$2:$Z$8725,0))='League Settings'!$B$2,"MINE","TAKEN"))),"") | AN10: Jackson LaCombe (ANA D) | AO10: =IFERROR(IF(INDEX('Player Pool'!$D$2:$D$8725,MATCH($AN10,'Player Pool'!$Z$2:$Z$8725,0))="","",INDEX('Player Pool'!$D$2:$D$8725,MATCH($AN10,'Player Pool'!$Z$2:$Z$8725,0))),"") | AP10: =IFERROR(IF(INDEX('Player Pool'!$E$2:$E$8725,MATCH($AN10,'Player Pool'!$Z$2:$Z$8725,0))="","",INDEX('Player Pool'!$E$2:$E$8725,MATCH($AN10,'Player Pool'!$Z$2:$Z$8725,0))),"") | AQ10: =IFERROR(IF($AN10="","",IF(ISNUMBER(IFERROR(INDEX(Rosters!$I$2:$I$516,MATCH(INDEX('Player Pool'!$V$2:$V$8725,MATCH($AN10,'Player Pool'!$Z$2:$Z$8725,0)),Rosters!$W$2:$W$516,0)),"")),IFERROR(INDEX(Rosters!$I$2:$I$516,MATCH(INDEX('Player Pool'!$V$2:$V$8725,MATCH($AN10,'Player Pool'!$Z$2:$Z$8725,0)),Rosters!$W$2:$W$516,0)),""),INDEX('Player Pool'!$H$2:$H$8725,MATCH($AN10,'Player Pool'!$Z$2:$Z$8725,0)))),"") | AR10: =IFERROR(IF(INDEX('Player Pool'!$I$2:$I$8725,MATCH($AN10,'Player Pool'!$Z$2:$Z$8725,0))="","",INDEX('Player Pool'!$I$2:$I$8725,MATCH($AN10,'Player Pool'!$Z$2:$Z$8725,0))),"") | AS10: =IFERROR(IF(INDEX('Player Pool'!$P$2:$P$8725,MATCH($AN10,'Player Pool'!$Z$2:$Z$8725,0))="","",INDEX('Player Pool'!$P$2:$P$8725,MATCH($AN10,'Player Pool'!$Z$2:$Z$8725,0))),"") | AT10: =IFERROR(IF(INDEX('Player Pool'!$R$2:$R$8725,MATCH($AN10,'Player Pool'!$Z$2:$Z$8725,0))="","",INDEX('Player Pool'!$R$2:$R$8725,MATCH($AN10,'Player Pool'!$Z$2:$Z$8725,0))),"") | AU10: =IFERROR(IF(INDEX('Player Pool'!$U$2:$U$8725,MATCH($AN10,'Player Pool'!$Z$2:$Z$8725,0))="","",INDEX('Player Pool'!$U$2:$U$8725,MATCH($AN10,'Player Pool'!$Z$2:$Z$8725,0))),"") | AV10: =IFERROR(IF($AN10="","",IF(INDEX('Player Pool'!$G$2:$G$8725,MATCH($AN10,'Player Pool'!$Z$2:$Z$8725,0))="FA","FA",IF(INDEX('Player Pool'!$G$2:$G$8725,MATCH($AN10,'Player Pool'!$Z$2:$Z$8725,0))='League Settings'!$B$2,"MINE","TAKEN"))),"")
A11: =IFERROR(IF(INDEX(Rosters!$B$2:$B$516,$S11)="","",INDEX(Rosters!$B$2:$B$516,$S11)),"") | B11: =IFERROR(IF(INDEX(Rosters!$C$2:$C$516,$S11)="","",INDEX(Rosters!$C$2:$C$516,$S11)),"") | C11: =IFERROR(IF(INDEX(Rosters!$D$2:$D$516,$S11)="","",INDEX(Rosters!$D$2:$D$516,$S11)),"") | D11: =IFERROR(IF(INDEX(Rosters!$E$2:$E$516,$S11)="","",INDEX(Rosters!$E$2:$E$516,$S11)),"") | E11: =IFERROR(IF(INDEX(Rosters!$F$2:$F$516,$S11)="","",INDEX(Rosters!$F$2:$F$516,$S11)),"") | F11: =IFERROR(IF(INDEX(Rosters!$G$2:$G$516,$S11)="","",INDEX(Rosters!$G$2:$G$516,$S11)),"") | G11: =IFERROR(IF(INDEX(Rosters!$H$2:$H$516,$S11)="","",INDEX(Rosters!$H$2:$H$516,$S11)),"") | H11: =IFERROR(IF(INDEX(Rosters!$I$2:$I$516,$S11)="","",INDEX(Rosters!$I$2:$I$516,$S11)),"") | I11: =IFERROR(IF(INDEX(Rosters!$J$2:$J$516,$S11)="","",INDEX(Rosters!$J$2:$J$516,$S11)),"") | J11: =IFERROR(IF(INDEX(Rosters!$S$2:$S$516,$S11)="","",INDEX(Rosters!$S$2:$S$516,$S11)),"") | K11: =IFERROR(IF(INDEX(Rosters!$K$2:$K$516,$S11)="","",INDEX(Rosters!$K$2:$K$516,$S11)),"") | L11: =IFERROR(IF(INDEX(Rosters!$T$2:$T$516,$S11)="","",INDEX(Rosters!$T$2:$T$516,$S11)),"") | M11: =IFERROR(IF(INDEX(Rosters!$L$2:$L$516,$S11)="","",INDEX(Rosters!$L$2:$L$516,$S11)),"") | N11: =IFERROR(IF(INDEX(Rosters!$Q$2:$Q$516,$S11)="","",INDEX(Rosters!$Q$2:$Q$516,$S11)),"") | O11: =IFERROR(IF(INDEX(Rosters!$R$2:$R$516,$S11)="","",INDEX(Rosters!$R$2:$R$516,$S11)),"") | P11: =IFERROR(IF(INDEX(Rosters!$N$2:$N$516,$S11)="","",INDEX(Rosters!$N$2:$N$516,$S11)),"") | Q11: =IFERROR(IF(INDEX(Rosters!$O$2:$O$516,$S11)="","",INDEX(Rosters!$O$2:$O$516,$S11)),"") | R11: =IFERROR(IF(INDEX(Rosters!$P$2:$P$516,$S11)="","",INDEX(Rosters!$P$2:$P$516,$S11)),"") | S11: =IFERROR(MATCH('League Settings'!$B$2&"|ACTIVE|"&8,Rosters!$AD$2:$AD$516,0),"") | T11: Morgan Geekie (BOS LW) | U11: =IFERROR(IF(INDEX('Player Pool'!$D$2:$D$8725,MATCH($T11,'Player Pool'!$Z$2:$Z$8725,0))="","",INDEX('Player Pool'!$D$2:$D$8725,MATCH($T11,'Player Pool'!$Z$2:$Z$8725,0))),"") | V11: =IFERROR(IF(INDEX('Player Pool'!$E$2:$E$8725,MATCH($T11,'Player Pool'!$Z$2:$Z$8725,0))="","",INDEX('Player Pool'!$E$2:$E$8725,MATCH($T11,'Player Pool'!$Z$2:$Z$8725,0))),"") | W11: =IFERROR(IF($T11="","",IF(ISNUMBER(IFERROR(INDEX(Rosters!$I$2:$I$516,MATCH(INDEX('Player Pool'!$V$2:$V$8725,MATCH($T11,'Player Pool'!$Z$2:$Z$8725,0)),Rosters!$W$2:$W$516,0)),"")),IFERROR(INDEX(Rosters!$I$2:$I$516,MATCH(INDEX('Player Pool'!$V$2:$V$8725,MATCH($T11,'Player Pool'!$Z$2:$Z$8725,0)),Rosters!$W$2:$W$516,0)),""),INDEX('Player Pool'!$H$2:$H$8725,MATCH($T11,'Player Pool'!$Z$2:$Z$8725,0)))),"") | X11: =IFERROR(IF(INDEX('Player Pool'!$I$2:$I$8725,MATCH($T11,'Player Pool'!$Z$2:$Z$8725,0))="","",INDEX('Player Pool'!$I$2:$I$8725,MATCH($T11,'Player Pool'!$Z$2:$Z$8725,0))),"") | Y11: =IFERROR(IF(INDEX('Player Pool'!$P$2:$P$8725,MATCH($T11,'Player Pool'!$Z$2:$Z$8725,0))="","",INDEX('Player Pool'!$P$2:$P$8725,MATCH($T11,'Player Pool'!$Z$2:$Z$8725,0))),"") | Z11: =IFERROR(IF(INDEX('Player Pool'!$R$2:$R$8725,MATCH($T11,'Player Pool'!$Z$2:$Z$8725,0))="","",INDEX('Player Pool'!$R$2:$R$8725,MATCH($T11,'Player Pool'!$Z$2:$Z$8725,0))),"") | AA11: =IFERROR(IF(INDEX('Player Pool'!$U$2:$U$8725,MATCH($T11,'Player Pool'!$Z$2:$Z$8725,0))="","",INDEX('Player Pool'!$U$2:$U$8725,MATCH($T11,'Player Pool'!$Z$2:$Z$8725,0))),"") | AB11: =IFERROR(IF($T11="","",IF(INDEX('Player Pool'!$G$2:$G$8725,MATCH($T11,'Player Pool'!$Z$2:$Z$8725,0))="FA","FA",IF(INDEX('Player Pool'!$G$2:$G$8725,MATCH($T11,'Player Pool'!$Z$2:$Z$8725,0))='League Settings'!$B$2,"MINE","TAKEN"))),"") | AD11: Morgan Geekie (BOS LW) | AE11: =IFERROR(IF(INDEX('Player Pool'!$D$2:$D$8725,MATCH($AD11,'Player Pool'!$Z$2:$Z$8725,0))="","",INDEX('Player Pool'!$D$2:$D$8725,MATCH($AD11,'Player Pool'!$Z$2:$Z$8725,0))),"") | AF11: =IFERROR(IF(INDEX('Player Pool'!$E$2:$E$8725,MATCH($AD11,'Player Pool'!$Z$2:$Z$8725,0))="","",INDEX('Player Pool'!$E$2:$E$8725,MATCH($AD11,'Player Pool'!$Z$2:$Z$8725,0))),"") | AG11: =IFERROR(IF($AD11="","",IF(ISNUMBER(IFERROR(INDEX(Rosters!$I$2:$I$516,MATCH(INDEX('Player Pool'!$V$2:$V$8725,MATCH($AD11,'Player Pool'!$Z$2:$Z$8725,0)),Rosters!$W$2:$W$516,0)),"")),IFERROR(INDEX(Rosters!$I$2:$I$516,MATCH(INDEX('Player Pool'!$V$2:$V$8725,MATCH($AD11,'Player Pool'!$Z$2:$Z$8725,0)),Rosters!$W$2:$W$516,0)),""),INDEX('Player Pool'!$H$2:$H$8725,MATCH($AD11,'Player Pool'!$Z$2:$Z$8725,0)))),"") | AH11: =IFERROR(IF(INDEX('Player Pool'!$I$2:$I$8725,MATCH($AD11,'Player Pool'!$Z$2:$Z$8725,0))="","",INDEX('Player Pool'!$I$2:$I$8725,MATCH($AD11,'Player Pool'!$Z$2:$Z$8725,0))),"") | AI11: =IFERROR(IF(INDEX('Player Pool'!$P$2:$P$8725,MATCH($AD11,'Player Pool'!$Z$2:$Z$8725,0))="","",INDEX('Player Pool'!$P$2:$P$8725,MATCH($AD11,'Player Pool'!$Z$2:$Z$8725,0))),"") | AJ11: =IFERROR(IF(INDEX('Player Pool'!$R$2:$R$8725,MATCH($AD11,'Player Pool'!$Z$2:$Z$8725,0))="","",INDEX('Player Pool'!$R$2:$R$8725,MATCH($AD11,'Player Pool'!$Z$2:$Z$8725,0))),"") | AK11: =IFERROR(IF(INDEX('Player Pool'!$U$2:$U$8725,MATCH($AD11,'Player Pool'!$Z$2:$Z$8725,0))="","",INDEX('Player Pool'!$U$2:$U$8725,MATCH($AD11,'Player Pool'!$Z$2:$Z$8725,0))),"") | AL11: =IFERROR(IF($AD11="","",IF(INDEX('Player Pool'!$G$2:$G$8725,MATCH($AD11,'Player Pool'!$Z$2:$Z$8725,0))="FA","FA",IF(INDEX('Player Pool'!$G$2:$G$8725,MATCH($AD11,'Player Pool'!$Z$2:$Z$8725,0))='League Settings'!$B$2,"MINE","TAKEN"))),"") | AN11: Morgan Geekie (BOS LW) | AO11: =IFERROR(IF(INDEX('Player Pool'!$D$2:$D$8725,MATCH($AN11,'Player Pool'!$Z$2:$Z$8725,0))="","",INDEX('Player Pool'!$D$2:$D$8725,MATCH($AN11,'Player Pool'!$Z$2:$Z$8725,0))),"") | AP11: =IFERROR(IF(INDEX('Player Pool'!$E$2:$E$8725,MATCH($AN11,'Player Pool'!$Z$2:$Z$8725,0))="","",INDEX('Player Pool'!$E$2:$E$8725,MATCH($AN11,'Player Pool'!$Z$2:$Z$8725,0))),"") | AQ11: =IFERROR(IF($AN11="","",IF(ISNUMBER(IFERROR(INDEX(Rosters!$I$2:$I$516,MATCH(INDEX('Player Pool'!$V$2:$V$8725,MATCH($AN11,'Player Pool'!$Z$2:$Z$8725,0)),Rosters!$W$2:$W$516,0)),"")),IFERROR(INDEX(Rosters!$I$2:$I$516,MATCH(INDEX('Player Pool'!$V$2:$V$8725,MATCH($AN11,'Player Pool'!$Z$2:$Z$8725,0)),Rosters!$W$2:$W$516,0)),""),INDEX('Player Pool'!$H$2:$H$8725,MATCH($AN11,'Player Pool'!$Z$2:$Z$8725,0)))),"") | AR11: =IFERROR(IF(INDEX('Player Pool'!$I$2:$I$8725,MATCH($AN11,'Player Pool'!$Z$2:$Z$8725,0))="","",INDEX('Player Pool'!$I$2:$I$8725,MATCH($AN11,'Player Pool'!$Z$2:$Z$8725,0))),"") | AS11: =IFERROR(IF(INDEX('Player Pool'!$P$2:$P$8725,MATCH($AN11,'Player Pool'!$Z$2:$Z$8725,0))="","",INDEX('Player Pool'!$P$2:$P$8725,MATCH($AN11,'Player Pool'!$Z$2:$Z$8725,0))),"") | AT11: =IFERROR(IF(INDEX('Player Pool'!$R$2:$R$8725,MATCH($AN11,'Player Pool'!$Z$2:$Z$8725,0))="","",INDEX('Player Pool'!$R$2:$R$8725,MATCH($AN11,'Player Pool'!$Z$2:$Z$8725,0))),"") | AU11: =IFERROR(IF(INDEX('Player Pool'!$U$2:$U$8725,MATCH($AN11,'Player Pool'!$Z$2:$Z$8725,0))="","",INDEX('Player Pool'!$U$2:$U$8725,MATCH($AN11,'Player Pool'!$Z$2:$Z$8725,0))),"") | AV11: =IFERROR(IF($AN11="","",IF(INDEX('Player Pool'!$G$2:$G$8725,MATCH($AN11,'Player Pool'!$Z$2:$Z$8725,0))="FA","FA",IF(INDEX('Player Pool'!$G$2:$G$8725,MATCH($AN11,'Player Pool'!$Z$2:$Z$8725,0))='League Settings'!$B$2,"MINE","TAKEN"))),"")
